Workbook

Sheet RAPORT XIIAKL 
B1: No | C1: 1
B3: Nama Peserta Didik | D3: =VLOOKUP($C$1,'LEGGER XII AKL'!$A$15:$BS$54,2,FALSE) -> Amelia | H3: Kelas | I3: ='LEGGER XII AKL'!C5 -> XII AKL
B4: N I S N | D4: =VLOOKUP($C$1,'LEGGER XII AKL'!$A$15:$BS$54,3,FALSE) -> 0068552301 | H4: Fase | I4: F
B5: Sekolah | D5: SMK YAJ | H5: Semester | I5: ='LEGGER XII AKL'!C6 -> 1 (SATU)
B6: Alamat | D6: Jl. Arridho RT. 01/04 No. 166 | H6: Tahun Pelajaran | I6: ='LEGGER XII AKL'!C7 -> 2024 /2025
B9: LAPORAN HASIL BELAJAR
B11: No. | C11: Mata Pelajaran | E11: Nilai Akhir | G11: Capaian Kompetensi
B13: A. KELOMPOK UMUM
B14: 1 | C14: Pendidikan Agama dan Budi Pekerti | E14: =VLOOKUP($C$1,'LEGGER XII AKL'!$A$15:$BS$54,8,FALSE) -> 87.666667 | F14: =IF(E14>=90,"Sangat Baik",IF(E14>=80,"Baik",IF(E14>=70,"Cukup","Perlu Bimbingan"))) -> Baik | G14: =VLOOKUP(F14,DESKRIPSI!$C$10:$O$13,2,FALSE) -> Peserta didik Mampu membaca, menghafal Q.S. Al-Baqarah/2: 155-156 dan mampu mempraktekkan Da’wah (Ceramah, Pidato, Khutbah), dzikir dan do’a setelah shalat Fardhu, serta tahlil dengan Baik.
B15: 2 | C15: Pendidikan Pancasila | E15: =VLOOKUP($C$1,'LEGGER XII AKL'!$A$15:$BS$54,13,FALSE) -> 95 | F15: =IF(E15>=90,"Sangat Baik",IF(E15>=80,"Baik",IF(E15>=70,"Cukup","Perlu Bimbingan"))) -> Sangat Baik | G15: =VLOOKUP(F15,DESKRIPSI!$C$10:$O$13,3,FALSE) -> Peserta didik mampu menjelaskan peran dan kewajiban warga negara Indonesia dalam menjaga persatuan dan kesatuan bangsa dengan Sangat Baik.
B16: 3 | C16: Bahasa Indonesia | E16: =VLOOKUP($C$1,'LEGGER XII AKL'!$A$15:$BS$54,18,FALSE) -> 92.333333 | F16: =IF(E16>=90,"Sangat Baik",IF(E16>=80,"Baik",IF(E16>=70,"Cukup","Perlu Bimbingan"))) -> Sangat Baik | G16: =VLOOKUP(F16,DESKRIPSI!$C$10:$O$13,4,FALSE) -> Peserta didik mampu menerapkan etika berkomunikasi secara lisan dan tulisan, integritas antara lain; jujur, disiplin, kemandirian dan tanggung jawab, etos kerja secara mandiri dan secara tim. Kependudukan sosial dan lingkungan, serta ketaatan terhadap norma, K3LH dan POS juga berlaku di dunia kerja dengan Sangat Baik.
B17: 4 | C17: Pendidikan Jasmani, Olahraga dan Kesehatan | E17: =VLOOKUP($C$1,'LEGGER XII AKL'!$A$15:$BS$54,23,FALSE) -> 0 | F17: =IF(E17>=90,"Sangat Baik",IF(E17>=80,"Baik",IF(E17>=70,"Cukup","Perlu Bimbingan"))) -> Perlu Bimbingan | G17: =VLOOKUP(F17,DESKRIPSI!$C$10:$O$13,5,FALSE) -> Konsep _ PENJAS _ Belum Kompeten
B18: 5 | C18: Sejarah | E18: =VLOOKUP($C$1,'LEGGER XII AKL'!$A$15:$BS$54,28,FALSE) -> 0 | F18: =IF(E18>=90,"Sangat Baik",IF(E18>=80,"Baik",IF(E18>=70,"Cukup","Perlu Bimbingan"))) -> Perlu Bimbingan | G18: =VLOOKUP(F18,DESKRIPSI!$C$10:$O$13,6,FALSE) -> Konsep _ SEJARAH _ Belum Kompeten
B19: 6 | C19: Seni Budaya | E19: =VLOOKUP($C$1,'LEGGER XII AKL'!$A$15:$BS$54,33,FALSE) -> 0 | F19: =IF(E19>=90,"Sangat Baik",IF(E19>=80,"Baik",IF(E19>=70,"Cukup","Perlu Bimbingan"))) -> Perlu Bimbingan | G19: =VLOOKUP(F19,DESKRIPSI!$C$10:$O$13,7,FALSE) -> Konsep _ SENI _ Belum Kompeten
B20: B. KELOMPOK KEJURUAN
B21: 4 | C21: Matematika | E21: =VLOOKUP($C$1,'LEGGER XII AKL'!$A$15:$BS$54,38,FALSE) -> 91.666667 | F21: =IF(E21>=90,"Sangat Baik",IF(E21>=80,"Baik",IF(E21>=70,"CUKUP","Perlu Bimbingan"))) -> Sangat Baik | G21: =VLOOKUP(F21,DESKRIPSI!$C$10:$O$13,8,FALSE) -> Peserta didik mampu memahami konsep peluang menggunakan Kaidah Pencacahan (Pengisian Tempat, Faktorial, Permutasi dan Kombinasi dengan Sangat Baik.
B22: 5 | C22: Bahasa Inggris | E22: =VLOOKUP($C$1,'LEGGER XII AKL'!$A$15:$BS$54,43,FALSE) -> 93.333333 | F22: =IF(E22>=90,"Sangat Baik",IF(E22>=80,"Baik",IF(E22>=70,"CUKUP","Perlu Bimbingan"))) -> Sangat Baik | G22: =VLOOKUP(F22,DESKRIPSI!$C$10:$O$13,9,FALSE) -> Peserta didik mampu menulis Surat lamaran kerja dan daftar riwayat hidup dalam Bahasa inggris secara benar dengan Sangat Baik.
B23: 6 | C23: Konsentrasi Keahlian | E23: =VLOOKUP($C$1,'LEGGER XII AKL'!$A$15:$BS$54,48,FALSE) -> 93 | F23: =IF(E23>=90,"Sangat Baik",IF(E23>=80,"Baik",IF(E23>=70,"CUKUP","Perlu Bimbingan"))) -> Sangat Baik | G23: =VLOOKUP(F23,DESKRIPSI!$C$10:$O$13,10,FALSE) -> Peserta didik mampu menganalisis perhitungan persediaan dengan berbagai metode, menganalisis rekonsiliasi bank, mampu menghitung PPh Pasal 21 terutang dan mampu memahami siklus akuntansi lembaga pemerintahan. Peserta didik mampu mencatat transaksi serta memposting ke dalam Jurnal Umum, Buku Besar, dan Neraca Saldo pada Perusahaan Jasa dengan Sangat Baik.
B24: 7 | C24: Projek Kreatif dan Kewirausahaan | E24: =VLOOKUP($C$1,'LEGGER XII AKL'!$A$15:$BS$54,53,FALSE) -> 30 | F24: =IF(E24>=90,"Sangat Baik",IF(E24>=80,"Baik",IF(E24>=70,"CUKUP","Perlu Bimbingan"))) -> Perlu Bimbingan | G24: =VLOOKUP(F24,DESKRIPSI!$C$10:$O$13,11,FALSE) -> Peserta didik belum mampu membaca peluang usaha dengan mengidentifikasi potensi yang ada di lingkungan internal dan eksternal SMK serta menetapkan jenis usaha, memasarkan produk dengan menentukan segmen pasar, menentukan harga produk, dan menentukan media yang digunakan untuk memasarkan produk dengan Perlu Bimbingan.
B25: 8 | C25: Mata Pelajaran Pilhan (Spreadsheet) | E25: =VLOOKUP($C$1,'LEGGER XII AKL'!$A$15:$BS$54,58,FALSE) -> 90.666667 | F25: =IF(E25>=90,"Sangat Baik",IF(E25>=80,"Baik",IF(E25>=70,"CUKUP","Perlu Bimbingan"))) -> Sangat Baik | G25: =VLOOKUP(F25,DESKRIPSI!$C$10:$O$13,12,FALSE) -> Peserta didik mampu membuat bukti transaksi pada Perusahaan Jasa dengan Sangat Baik.
B26: MUATAN LOKAL
B27: 9 | C27: Dasar Design Grafis | E27: =VLOOKUP($C$1,'LEGGER XII AKL'!$A$15:$BS$54,63,FALSE) -> 92.666667 | F27: =IF(E27>=90,"Sangat Baik",IF(E27>=80,"Baik",IF(E27>=70,"CUKUP","Perlu Bimbingan"))) -> Sangat Baik | G27: =VLOOKUP(F27,DESKRIPSI!$C$10:$O$13,13,FALSE) -> Peserta didik mampu menerapkan penggunaan layer untuk pengelolaan objek dalam desain dengan Sangat Baik.
B30: No. | C30: Ekstrakurikuler | E30: Predikat | G30: Keterangan
B31: 1. | C31: =VLOOKUP($C$1,EKSKUL!$A$16:$O$60,4,FALSE) -> - | E31: =VLOOKUP($C$1,EKSKUL!$A$16:$O$60,6,FALSE) -> - | G31: =VLOOKUP($C$1,EKSKUL!$A$16:$O$60,7,FALSE) -> -
B32: 2. | C32: =VLOOKUP($C$1,EKSKUL!$A$16:$O$60,8,FALSE) -> - | E32: =VLOOKUP($C$1,EKSKUL!$A$16:$O$60,10,FALSE) -> - | G32: =VLOOKUP($C$1,EKSKUL!$A$16:$O$60,11,FALSE) -> -
B33: 3. | C33: =VLOOKUP($C$1,EKSKUL!$A$16:$O$60,12,FALSE) -> - | E33: =VLOOKUP($C$1,EKSKUL!$A$16:$O$60,14,FALSE) -> - | G33: =VLOOKUP($C$1,EKSKUL!$A$16:$O$60,15,FALSE) -> -
B35: Total Nilai | D35: =VLOOKUP($C$1,'LEGGER XII AKL'!$A$15:$BS$54,64,FALSE) -> 766.33333 | G35: Peringkat Ke | H35: =VLOOKUP($C$1,'CATATAN WALAS'!$A$15:$O$59,5,FALSE) -> 32
B36: Nilai Rata-Rata | D36: =VLOOKUP($C$1,'LEGGER XII AKL'!$A$15:$BS$54,65,FALSE) -> 85.148148 | H36: ="Dari "&'LEGGER XII AKL'!I5&" Siswa" -> Dari 32 Siswa
B38: Ketidak Hadiran | G38: Catatan Wali Kelas
B39: Sakit | D39: =VLOOKUP($C$1,'LEGGER XII AKL'!$A$15:$BS$54,69,FALSE)&" hari" -> 2 hari | G39: =VLOOKUP($C$1,'CATATAN WALAS'!$A$15:$O$59,6,FALSE) -> Jangan menyerah, tingkatkan kembali belajarmu
B40: Ijin | D40: =VLOOKUP($C$1,'LEGGER XII AKL'!$A$15:$BS$54,70,FALSE)&" hari" -> 1 hari
B41: Tanpa Keterangan | D41: =VLOOKUP($C$1,'LEGGER XII AKL'!$A$15:$BS$54,71,FALSE)&" hari" -> 0 hari
I45: Depok, 20 Desember 2024
C46: Orangtua / Wali, | I46: Wali Kelas
I50: ='LEGGER XII AKL'!I6 -> Elsa Wahyuningrum, A.Md. KA.
I51: NIP. -
G52: Mengetahui,
G53: Kepala Sekolah,
G58: Idham Kholid, S. Ag., S. E.
G59: NIP. -
...

Sheet LEGGER XII AKL
A1: LEGGER HASIL BELAJAR SISWA
A2: PERIODE SEMESTER GANJIL TAHUN PELAJARAN 2024/2025
A3: SMK YAJ
B5: KELAS | C5: XII AKL | F5: JUMLAH SISWA | I5: =COUNTA(B15:B59) -> 32 | J5: Siswa
B6: SEMESTER | C6: 1 (SATU) | F6: NAMA WALI KELAS | I6: Elsa Wahyuningrum, A.Md. KA.
B7: TAHUN PELAJARAN | C7: 2024 /2025 | F7: NIP / NUPTK | I7: -
A9: 1 | B9: 2 | C9: 3 | D9: 4 | E9: 5 | F9: 6 | G9: 7 | H9: 8 | I9: 9 | J9: 10 | K9: 11 | L9: 12 | M9: 13 | N9: 14 | O9: 15 | P9: 16 | Q9: 17 | R9: 18 | S9: 19 | T9: 20 | U9: 21 | V9: 22 | W9: 23 | X9: 24 | Y9: 25 | Z9: 26 | AA9: 27 | AB9: 28 | AC9: 29 | AD9: 30 | AE9: 31 | AF9: 32 | AG9: 33 | AH9: 34 | AI9: 35 | AJ9: 36 | AK9: 37 | AL9: 38 | AM9: 39 | AN9: 40 | AO9: 41 | AP9: 42 | AQ9: 43 | AR9: 44 | AS9: 45 | AT9: 46 | AU9: 47 | AV9: 48 | AW9: 49 | AX9: 50 | AY9: 51 | AZ9: 52 | BA9: 53 | BB9: 54 | BC9: 55 | BD9: 56 | BE9: 57 | BF9: 58 | BG9: 59 | BH9: 60 | BI9: 61 | BJ9: 62 | BK9: 63 | BL9: 64 | BM9: 65 | BN9: 66 | BO9: 67 | BP9: 68 | BQ9: 69 | BR9: 70 | BS9: 71
A11: NO | B11: NAMA SISWA | C11: N I S N | D11: KELOMPOK UMUM #1 | I11: KELOMPOK UMUM #2 | N11: KELOMPOK UMUM #3 | S11: KELOMPOK UMUM #4 | X11: KELOMPOK UMUM #5 | AC11: KELOMPOK UMUM #6 | AH11: KELOMPOK KEJURUAN #1 | AM11: KELOMPOK KEJURUAN #2 | AR11: KELOMPOK KEJURUAN #3 | AW11: KELOMPOK KEJURUAN #4 | BB11: KELOMPOK KEJURUAN #5 | BG11: MUATAN LOKAL #1 | BL11: Total Nilai | BM11: Rata-Rata | BQ11: KETIDAKHADIRAN
D12: ='RAPORT XIIAKL '!$C14 -> Pendidikan Agama dan Budi Pekerti | I12: ='RAPORT XIIAKL '!$C15 -> Pendidikan Pancasila | N12: ='RAPORT XIIAKL '!$C16 -> Bahasa Indonesia | S12: ='RAPORT XIIAKL '!$C17 -> Pendidikan Jasmani, Olahraga dan Kesehatan | X12: ='RAPORT XIIAKL '!$C18 -> Sejarah | AC12: ='RAPORT XIIAKL '!$C19 -> Seni Budaya | AH12: ='RAPORT XIIAKL '!$C21 -> Matematika | AM12: ='RAPORT XIIAKL '!$C22 -> Bahasa Inggris | AR12: ='RAPORT XIIAKL '!$C23 -> Konsentrasi Keahlian | AW12: ='RAPORT XIIAKL '!$C24 -> Projek Kreatif dan Kewirausahaan | BB12: ='RAPORT XIIAKL '!$C25 -> Mata Pelajaran Pilhan (Spreadsheet) | BG12: ='RAPORT XIIAKL '!$C27 -> Dasar Design Grafis
D13: RERATA TUGAS/PH/Assessment | E13: FORMATIF/P.T.S. | F13: SUMATIF/P.A.S. | G13: KEHADIRAN | H13: NILAI AKHIR | I13: RERATA TUGAS/PH/Assessment | J13: FORMATIF/P.T.S. | K13: SUMATIF/P.A.S. | L13: KEHADIRAN | M13: NILAI AKHIR | N13: RERATA TUGAS/PH/Assessment | O13: FORMATIF/P.T.S. | P13: SUMATIF/P.A.S. | Q13: KEHADIRAN | R13: NILAI AKHIR | S13: RERATA TUGAS/PH/Assessment | T13: FORMATIF/P.T.S. | U13: SUMATIF/P.A.S. | V13: KEHADIRAN | W13: NILAI AKHIR | X13: RERATA TUGAS/PH/Assessment | Y13: FORMATIF/P.T.S. | Z13: SUMATIF/P.A.S. | AA13: KEHADIRAN | AB13: NILAI AKHIR | AC13: RERATA TUGAS/PH/Assessment | AD13: FORMATIF/P.T.S. | AE13: SUMATIF/P.A.S. | AF13: KEHADIRAN | AG13: NILAI AKHIR | AH13: RERATA TUGAS/PH/Assessment | AI13: FORMATIF/P.T.S. | AJ13: SUMATIF/P.A.S. | AK13: KEHADIRAN | AL13: NILAI AKHIR | AM13: RERATA TUGAS/PH/Assessment | AN13: FORMATIF/P.T.S. | AO13: SUMATIF/P.A.S. | AP13: KEHADIRAN | AQ13: NILAI AKHIR | AR13: RERATA TUGAS/PH/Assessment | AS13: FORMATIF/P.T.S. | AT13: SUMATIF/P.A.S. | AU13: KEHADIRAN | AV13: NILAI AKHIR | AW13: RERATA TUGAS/PH/Assessment | AX13: FORMATIF/P.T.S. | AY13: SUMATIF/P.A.S. | AZ13: KEHADIRAN | BA13: NILAI AKHIR | BB13: RERATA TUGAS/PH/Assessment | BC13: FORMATIF/P.T.S. | BD13: SUMATIF/P.A.S. | BE13: KEHADIRAN | BF13: NILAI AKHIR | BG13: RERATA TUGAS/PH/Assessment | BH13: FORMATIF/P.T.S. | BI13: SUMATIF/P.A.S. | BJ13: KEHADIRAN | BK13: NILAI AKHIR | BQ13: SAKIT | BR13: IJIN | BS13: ALPA
A15: 1 | B15: Amelia | C15: 0068552301 | D15: 85 | F15: 84 | G15: 94 | H15: =(D15+E15+F15+G15)/3 -> 87.666667 | I15: 90 | K15: 95 | L15: 100 | M15: =(I15+J15+K15+L15)/3 -> 95 | N15: 88 | P15: 89 | Q15: 100 | R15: =(N15+O15+P15+Q15)/3 -> 92.333333 | W15: =(S15+T15+U15+V15)/4 -> 0 | AB15: =(X15+Y15+Z15+AA15)/4 -> 0 | AG15: =(AC15+AD15+AE15+AF15)/4 -> 0 | AH15: 90 | AJ15: 95 | AK15: 90 | AL15: =(AH15+AI15+AJ15+AK15)/3 -> 91.666667 | AM15: 90 | AO15: 90 | AP15: 100 | AQ15: =(AM15+AN15+AO15+AP15)/3 -> 93.333333 | AR15: 92 | AT15: 87 | AU15: 100 | AV15: =(AR15+AS15+AT15+AU15)/3 -> 93 | AZ15: 90 | BA15: =(AW15+AX15+AY15+AZ15)/3 -> 30 | BB15: 87 | BD15: 85 | BE15: 100 | BF15: =(BB15+BC15+BD15+BE15)/3 -> 90.666667 | BG15: 90 | BI15: 88 | BJ15: 100 | BK15: =(BG15+BH15+BI15+BJ15)/3 -> 92.666667 | BL15: =H15+M15+R15+W15+AB15+AL15+AQ15+AV15+BA15+BF15+BK15 -> 766.33333 | BM15: =BL15/9 -> 85.148148 | BQ15: 2 | BR15: 1 | BS15: 0
A16: 2 | B16: Chrycen Rivia Disa | C16: 0076793345 | D16: 86 | F16: 78 | G16: 94 | H16: =(D16+E16+F16+G16)/3 -> 86 | I16: 95 | K16: 90 | L16: 100 | M16: =(I16+J16+K16+L16)/3 -> 95 | N16: 88 | P16: 89 | Q16: 100 | R16: =(N16+O16+P16+Q16)/3 -> 92.333333 | W16: =(S16+T16+U16+V16)/4 -> 0 | AB16: =(X16+Y16+Z16+AA16)/4 -> 0 | AG16: =(AC16+AD16+AE16+AF16)/4 -> 0 | AH16: 90 | AJ16: 95 | AK16: 95 | AL16: =(AH16+AI16+AJ16+AK16)/3 -> 93.333333 | AM16: 88 | AO16: 92 | AP16: 100 | AQ16: =(AM16+AN16+AO16+AP16)/3 -> 93.333333 | AR16: 90 | AT16: 86 | AU16: 100 | AV16: =(AR16+AS16+AT16+AU16)/3 -> 92 | AW16: 90 | AY16: 89 | AZ16: 95 | BA16: =(AW16+AX16+AY16+AZ16)/3 -> 91.333333 | BB16: 85 | BD16: 85 | BE16: 100 | BF16: =(BB16+BC16+BD16+BE16)/3 -> 90 | BG16: 90 | BI16: 92 | BJ16: 100 | BK16: =(BG16+BH16+BI16+BJ16)/3 -> 94 | BL16: =H16+M16+R16+W16+AB16+AL16+AQ16+AV16+BA16+BF16+BK16 -> 827.33333 | BM16: =BL16/9 -> 91.925926 | BQ16: 2 | BR16: 2 | BS16: 0
A17: 3 | B17: Citra Attailah | C17: 0075546309 | D17: 86 | F17: 80 | G17: 94 | H17: =(D17+E17+F17+G17)/3 -> 86.666667 | I17: 90 | K17: 95 | L17: 100 | M17: =(I17+J17+K17+L17)/3 -> 95 | N17: 85 | P17: 89 | Q17: 100 | R17: =(N17+O17+P17+Q17)/3 -> 91.333333 | W17: =(S17+T17+U17+V17)/4 -> 0 | AB17: =(X17+Y17+Z17+AA17)/4 -> 0 | AG17: =(AC17+AD17+AE17+AF17)/4 -> 0 | AH17: 90 | AJ17: 95 | AK17: 95 | AL17: =(AH17+AI17+AJ17+AK17)/3 -> 93.333333 | AM17: 88 | AO17: 92 | AP17: 100 | AQ17: =(AM17+AN17+AO17+AP17)/3 -> 93.333333 | AR17: 92 | AT17: 90.5 | AU17: 100 | AV17: =(AR17+AS17+AT17+AU17)/3 -> 94.166667 | AW17: 90 | AY17: 88 | AZ17: 98 | BA17: =(AW17+AX17+AY17+AZ17)/3 -> 92 | BB17: 86 | BD17: 85 | BE17: 100 | BF17: =(BB17+BC17+BD17+BE17)/3 -> 90.333333 | BG17: 90 | BI17: 89 | BJ17: 100 | BK17: =(BG17+BH17+BI17+BJ17)/3 -> 93 | BL17: =H17+M17+R17+W17+AB17+AL17+AQ17+AV17+BA17+BF17+BK17 -> 829.16667 | BM17: =BL17/9 -> 92.12963 | BQ17: 0 | BR17: 1 | BS17: 0
A18: 4 | B18: Dimas Setiawan | C18: 0073521089 | D18: 88 | F18: 78 | G18: 94 | H18: =(D18+E18+F18+G18)/3 -> 86.666667 | I18: 80 | K18: 95 | L18: 100 | M18: =(I18+J18+K18+L18)/3 -> 91.666667 | N18: 83 | P18: 89 | Q18: 100 | R18: =(N18+O18+P18+Q18)/3 -> 90.666667 | W18: =(S18+T18+U18+V18)/4 -> 0 | AB18: =(X18+Y18+Z18+AA18)/4 -> 0 | AG18: =(AC18+AD18+AE18+AF18)/4 -> 0 | AH18: 80 | AJ18: 85 | AK18: 95 | AL18: =(AH18+AI18+AJ18+AK18)/3 -> 86.666667 | AM18: 88 | AO18: 92 | AP18: 100 | AQ18: =(AM18+AN18+AO18+AP18)/3 -> 93.333333 | AR18: 93 | AT18: 90.5 | AU18: 100 | AV18: =(AR18+AS18+AT18+AU18)/3 -> 94.5 | AW18: 90 | AY18: 90 | AZ18: 97 | BA18: =(AW18+AX18+AY18+AZ18)/3 -> 92.333333 | BB18: 89 | BD18: 87 | BE18: 100 | BF18: =(BB18+BC18+BD18+BE18)/3 -> 92 | BG18: 90 | BI18: 89 | BJ18: 100 | BK18: =(BG18+BH18+BI18+BJ18)/3 -> 93 | BL18: =H18+M18+R18+W18+AB18+AL18+AQ18+AV18+BA18+BF18+BK18 -> 820.83333 | BM18: =BL18/9 -> 91.203704 | BQ18: 3 | BR18: 0 | BS18: 0
A19: 5 | B19: Fadhil Ubaidillah | C19: 0063430650 | D19: 88 | F19: 88 | G19: 100 | H19: =(D19+E19+F19+G19)/3 -> 92 | I19: 85 | K19: 95 | L19: 100 | M19: =(I19+J19+K19+L19)/3 -> 93.333333 | N19: 89 | P19: 89 | Q19: 100 | R19: =(N19+O19+P19+Q19)/3 -> 92.666667 | W19: =(S19+T19+U19+V19)/4 -> 0 | AB19: =(X19+Y19+Z19+AA19)/4 -> 0 | AG19: =(AC19+AD19+AE19+AF19)/4 -> 0 | AH19: 90 | AJ19: 98 | AK19: 100 | AL19: =(AH19+AI19+AJ19+AK19)/3 -> 96 | AM19: 90 | AO19: 92 | AP19: 100 | AQ19: =(AM19+AN19+AO19+AP19)/3 -> 94 | AR19: 92 | AT19: 87.5 | AU19: 100 | AV19: =(AR19+AS19+AT19+AU19)/3 -> 93.166667 | AW19: 91 | AY19: 89 | AZ19: 96 | BA19: =(AW19+AX19+AY19+AZ19)/3 -> 92 | BB19: 89 | BD19: 87 | BE19: 100 | BF19: =(BB19+BC19+BD19+BE19)/3 -> 92 | BG19: 90 | BI19: 92 | BJ19: 100 | BK19: =(BG19+BH19+BI19+BJ19)/3 -> 94 | BL19: =H19+M19+R19+W19+AB19+AL19+AQ19+AV19+BA19+BF19+BK19 -> 839.16667 | BM19: =BL19/9 -> 93.240741 | BQ19: 0 | BR19: 0 | BS19: 0
A20: 6 | B20: Ferza Febriansyah | C20: 0071685041 | D20: 90 | F20: 90 | G20: 100 | H20: =(D20+E20+F20+G20)/3 -> 93.333333 | I20: 85 | K20: 95 | L20: 100 | M20: =(I20+J20+K20+L20)/3 -> 93.333333 | N20: 95 | P20: 89 | Q20: 100 | R20: =(N20+O20+P20+Q20)/3 -> 94.666667 | W20: =(S20+T20+U20+V20)/4 -> 0 | AB20: =(X20+Y20+Z20+AA20)/4 -> 0 | AG20: =(AC20+AD20+AE20+AF20)/4 -> 0 | AH20: 95 | AJ20: 98 | AK20: 100 | AL20: =(AH20+AI20+AJ20+AK20)/3 -> 97.666667 | AM20: 92 | AO20: 95 | AP20: 100 | AQ20: =(AM20+AN20+AO20+AP20)/3 -> 95.666667 | AR20: 95 | AT20: 95 | AU20: 100 | AV20: =(AR20+AS20+AT20+AU20)/3 -> 96.666667 | AW20: 90 | AY20: 90 | AZ20: 97 | BA20: =(AW20+AX20+AY20+AZ20)/3 -> 92.333333 | BB20: 90 | BD20: 90 | BE20: 100 | BF20: =(BB20+BC20+BD20+BE20)/3 -> 93.333333 | BG20: 90 | BI20: 92 | BJ20: 100 | BK20: =(BG20+BH20+BI20+BJ20)/3 -> 94 | BL20: =H20+M20+R20+W20+AB20+AL20+AQ20+AV20+BA20+BF20+BK20 -> 851 | BM20: =BL20/9 -> 94.555556 | BQ20: 0 | BR20: 0 | BS20: 0
A21: 7 | B21: Iqlimah Cahaya Mustika | C21: 0064268039 | D21: 85 | F21: 78 | G21: 100 | H21: =(D21+E21+F21+G21)/3 -> 87.666667 | I21: 68 | K21: 89 | L21: 100 | M21: =(I21+J21+K21+L21)/3 -> 85.666667 | N21: 83 | P21: 89 | Q21: 100 | R21: =(N21+O21+P21+Q21)/3 -> 90.666667 | W21: =(S21+T21+U21+V21)/4 -> 0 | AB21: =(X21+Y21+Z21+AA21)/4 -> 0 | AG21: =(AC21+AD21+AE21+AF21)/4 -> 0 | AH21: 75 | AJ21: 95 | AK21: 80 | AL21: =(AH21+AI21+AJ21+AK21)/3 -> 83.333333 | AM21: 85 | AO21: 90 | AP21: 100 | AQ21: =(AM21+AN21+AO21+AP21)/3 -> 91.666667 | AR21: 81 | AT21: 82 | AU21: 100 | AV21: =(AR21+AS21+AT21+AU21)/3 -> 87.666667 | AW21: 90 | AY21: 90 | AZ21: 98 | BA21: =(AW21+AX21+AY21+AZ21)/3 -> 92.666667 | BB21: 82 | BD21: 82 | BE21: 100 | BF21: =(BB21+BC21+BD21+BE21)/3 -> 88 | BG21: 90 | BI21: 93 | BJ21: 100 | BK21: =(BG21+BH21+BI21+BJ21)/3 -> 94.333333 | BL21: =H21+M21+R21+W21+AB21+AL21+AQ21+AV21+BA21+BF21+BK21 -> 801.66667 | BM21: =BL21/9 -> 89.074074 | BQ21: 0 | BR21: 0 | BS21: 0
A22: 8 | B22: Irshal Rhama Aidillah | C22: 3074487136 | D22: 85 | F22: 78 | G22: 100 | H22: =(D22+E22+F22+G22)/3 -> 87.666667 | I22: 80 | K22: 95 | L22: 100 | M22: =(I22+J22+K22+L22)/3 -> 91.666667 | N22: 87 | P22: 89 | Q22: 100 | R22: =(N22+O22+P22+Q22)/3 -> 92 | W22: =(S22+T22+U22+V22)/4 -> 0 | AB22: =(X22+Y22+Z22+AA22)/4 -> 0 | AG22: =(AC22+AD22+AE22+AF22)/4 -> 0 | AH22: 90 | AJ22: 85 | AK22: 100 | AL22: =(AH22+AI22+AJ22+AK22)/3 -> 91.666667 | AM22: 88 | AO22: 92 | AP22: 100 | AQ22: =(AM22+AN22+AO22+AP22)/3 -> 93.333333 | AR22: 92 | AT22: 87 | AU22: 100 | AV22: =(AR22+AS22+AT22+AU22)/3 -> 93 | AW22: 91 | AY22: 91 | AZ22: 96 | BA22: =(AW22+AX22+AY22+AZ22)/3 -> 92.666667 | BB22: 85 | BD22: 85 | BE22: 100 | BF22: =(BB22+BC22+BD22+BE22)/3 -> 90 | BG22: 90 | BI22: 93 | BJ22: 100 | BK22: =(BG22+BH22+BI22+BJ22)/3 -> 94.333333 | BL22: =H22+M22+R22+W22+AB22+AL22+AQ22+AV22+BA22+BF22+BK22 -> 826.33333 | BM22: =BL22/9 -> 91.814815 | BQ22: 1 | BR22: 0 | BS22: 0
A23: 9 | B23: Jingga Nur Qalam | C23: 0067481076 | D23: 85 | F23: 78 | G23: 100 | H23: =(D23+E23+F23+G23)/3 -> 87.666667 | I23: 90 | K23: 89 | L23: 100 | M23: =(I23+J23+K23+L23)/3 -> 93 | N23: 85 | P23: 89 | Q23: 100 | R23: =(N23+O23+P23+Q23)/3 -> 91.333333 | W23: =(S23+T23+U23+V23)/4 -> 0 | AB23: =(X23+Y23+Z23+AA23)/4 -> 0 | AG23: =(AC23+AD23+AE23+AF23)/4 -> 0 | AH23: 85 | AJ23: 95 | AK23: 90 | AL23: =(AH23+AI23+AJ23+AK23)/3 -> 90 | AM23: 90 | AO23: 90 | AP23: 100 | AQ23: =(AM23+AN23+AO23+AP23)/3 -> 93.333333 | AR23: 91.5 | AT23: 90 | AU23: 100 | AV23: =(AR23+AS23+AT23+AU23)/3 -> 93.833333 | AW23: 90 | AY23: 89 | AZ23: 95 | BA23: =(AW23+AX23+AY23+AZ23)/3 -> 91.333333 | BB23: 82 | BD23: 82 | BE23: 100 | BF23: =(BB23+BC23+BD23+BE23)/3 -> 88 | BG23: 90 | BI23: 89 | BJ23: 100 | BK23: =(BG23+BH23+BI23+BJ23)/3 -> 93 | BL23: =H23+M23+R23+W23+AB23+AL23+AQ23+AV23+BA23+BF23+BK23 -> 821.5 | BM23: =BL23/9 -> 91.277778 | BQ23: 4 | BR23: 0 | BS23: 0
A24: 10 | B24: Karina Dwi Sagita | C24: 0057659388 | D24: 85 | F24: 80 | G24: 100 | H24: =(D24+E24+F24+G24)/3 -> 88.333333 | I24: 68 | K24: 90 | L24: 100 | M24: =(I24+J24+K24+L24)/3 -> 86 | N24: 84 | P24: 89 | Q24: 100 | R24: =(N24+O24+P24+Q24)/3 -> 91 | W24: =(S24+T24+U24+V24)/4 -> 0 | AB24: =(X24+Y24+Z24+AA24)/4 -> 0 | AG24: =(AC24+AD24+AE24+AF24)/4 -> 0 | AH24: 75 | AJ24: 95 | AK24: 80 | AL24: =(AH24+AI24+AJ24+AK24)/3 -> 83.333333 | AM24: 88 | AO24: 90 | AP24: 100 | AQ24: =(AM24+AN24+AO24+AP24)/3 -> 92.666667 | AR24: 85 | AT24: 82 | AU24: 100 | AV24: =(AR24+AS24+AT24+AU24)/3 -> 89 | AW24: 90 | AY24: 88 | AZ24: 98 | BA24: =(AW24+AX24+AY24+AZ24)/3 -> 92 | BB24: 82 | BD24: 82 | BE24: 100 | BF24: =(BB24+BC24+BD24+BE24)/3 -> 88 | BG24: 90 | BI24: 92 | BJ24: 100 | BK24: =(BG24+BH24+BI24+BJ24)/3 -> 94 | BL24: =H24+M24+R24+W24+AB24+AL24+AQ24+AV24+BA24+BF24+BK24 -> 804.33333 | BM24: =BL24/9 -> 89.37037 | BQ24: 0 | BR24: 0 | BS24: 0
A25: 11 | B25: Larasati | C25: 3073371186 | D25: 85 | F25: 78 | G25: 100 | H25: =(D25+E25+F25+G25)/3 -> 87.666667 | I25: 68 | K25: 89 | L25: 100 | M25: =(I25+J25+K25+L25)/3 -> 85.666667 | N25: 82 | P25: 89 | Q25: 100 | R25: =(N25+O25+P25+Q25)/3 -> 90.333333 | W25: =(S25+T25+U25+V25)/4 -> 0 | AB25: =(X25+Y25+Z25+AA25)/4 -> 0 | AG25: =(AC25+AD25+AE25+AF25)/4 -> 0 | AH25: 75 | AJ25: 85 | AK25: 80 | AL25: =(AH25+AI25+AJ25+AK25)/3 -> 80 | AM25: 88 | AO25: 90 | AP25: 100 | AQ25: =(AM25+AN25+AO25+AP25)/3 -> 92.666667 | AR25: 87.5 | AT25: 83.5 | AU25: 100 | AV25: =(AR25+AS25+AT25+AU25)/3 -> 90.333333 | AW25: 90 | AY25: 92 | AZ25: 97 | BA25: =(AW25+AX25+AY25+AZ25)/3 -> 93 | BB25: 82 | BD25: 82 | BE25: 100 | BF25: =(BB25+BC25+BD25+BE25)/3 -> 88 | BG25: 90 | BI25: 87 | BJ25: 100 | BK25: =(BG25+BH25+BI25+BJ25)/3 -> 92.333333 | BL25: =H25+M25+R25+W25+AB25+AL25+AQ25+AV25+BA25+BF25+BK25 -> 800 | BM25: =BL25/9 -> 88.888889 | BQ25: 0 | BR25: 0 | BS25: 0
A26: 12 | B26: Lia Apriyani | C26: 0074403542 | D26: 87 | F26: 78 | G26: 100 | H26: =(D26+E26+F26+G26)/3 -> 88.333333 | I26: 90 | K26: 90 | L26: 100 | M26: =(I26+J26+K26+L26)/3 -> 93.333333 | N26: 88 | P26: 89 | Q26: 100 | R26: =(N26+O26+P26+Q26)/3 -> 92.333333 | W26: =(S26+T26+U26+V26)/4 -> 0 | AB26: =(X26+Y26+Z26+AA26)/4 -> 0 | AG26: =(AC26+AD26+AE26+AF26)/4 -> 0 | AH26: 80 | AJ26: 95 | AK26: 95 | AL26: =(AH26+AI26+AJ26+AK26)/3 -> 90 | AM26: 90 | AO26: 95 | AP26: 100 | AQ26: =(AM26+AN26+AO26+AP26)/3 -> 95 | AR26: 88 | AT26: 87 | AU26: 100 | AV26: =(AR26+AS26+AT26+AU26)/3 -> 91.666667 | AW26: 90 | AY26: 90 | AZ26: 96 | BA26: =(AW26+AX26+AY26+AZ26)/3 -> 92 | BB26: 82 | BD26: 82 | BE26: 100 | BF26: =(BB26+BC26+BD26+BE26)/3 -> 88 | BG26: 90 | BI26: 88 | BJ26: 100 | BK26: =(BG26+BH26+BI26+BJ26)/3 -> 92.666667 | BL26: =H26+M26+R26+W26+AB26+AL26+AQ26+AV26+BA26+BF26+BK26 -> 823.33333 | BM26: =BL26/9 -> 91.481481 | BQ26: 0 | BR26: 1 | BS26: 0
A27: 13 | B27: Lulu Amanda | C27: 0078516371 | D27: 90 | F27: 88 | G27: 100 | H27: =(D27+E27+F27+G27)/3 -> 92.666667 | I27: 80 | K27: 95 | L27: 100 | M27: =(I27+J27+K27+L27)/3 -> 91.666667 | N27: 89 | P27: 89 | Q27: 100 | R27: =(N27+O27+P27+Q27)/3 -> 92.666667 | W27: =(S27+T27+U27+V27)/4 -> 0 | AB27: =(X27+Y27+Z27+AA27)/4 -> 0 | AG27: =(AC27+AD27+AE27+AF27)/4 -> 0 | AH27: 90 | AJ27: 95 | AK27: 95 | AL27: =(AH27+AI27+AJ27+AK27)/3 -> 93.333333 | AM27: 90 | AO27: 92 | AP27: 100 | AQ27: =(AM27+AN27+AO27+AP27)/3 -> 94 | AR27: 95 | AT27: 95 | AU27: 100 | AV27: =(AR27+AS27+AT27+AU27)/3 -> 96.666667 | AW27: 91 | AY27: 89 | AZ27: 97 | BA27: =(AW27+AX27+AY27+AZ27)/3 -> 92.333333 | BB27: 90 | BD27: 90 | BE27: 100 | BF27: =(BB27+BC27+BD27+BE27)/3 -> 93.333333 | BG27: 90 | BI27: 88 | BJ27: 100 | BK27: =(BG27+BH27+BI27+BJ27)/3 -> 92.666667 | BL27: =H27+M27+R27+W27+AB27+AL27+AQ27+AV27+BA27+BF27+BK27 -> 839.33333 | BM27: =BL27/9 -> 93.259259 | BQ27: 2 | BR27: 0 | BS27: 0
... A46: 32 | B46: Zafira Raysa Umar | C46: 0073130066 | D46: 85 | F46: 78 | G46: 88 | H46: =(D46+E46+F46+G46)/3 -> 83.666667 | I46: 90 | K46: 90 | L46: 100 | M46: =(I46+J46+K46+L46)/3 -> 93.333333 | N46: 84 | P46: 89 | Q46: 100 | R46: =(N46+O46+P46+Q46)/3 -> 91 | W46: =(S46+T46+U46+V46)/4 -> 0 | AB46: =(X46+Y46+Z46+AA46)/4 -> 0 | AG46: =(AC46+AD46+AE46+AF46)/4 -> 0 | AH46: 90 | AJ46: 95 | AK46: 85 | AL46: =(AH46+AI46+AJ46+AK46)/3 -> 90 | AM46: 90 | AO46: 92 | AP46: 100 | AQ46: =(AM46+AN46+AO46+AP46)/3 -> 94 | AR46: 93 | AT46: 85.5 | AU46: 100 | AV46: =(AR46+AS46+AT46+AU46)/3 -> 92.833333 | AW46: 90 | AY46: 90 | AZ46: 98 | BA46: =(AW46+AX46+AY46+AZ46)/3 -> 92.666667 | BB46: 88 | BD46: 88 | BE46: 100 | BF46: =(BB46+BC46+BD46+BE46)/3 -> 92 | BG46: 90 | BI46: 92 | BJ46: 100 | BK46: =(BG46+BH46+BI46+BJ46)/3 -> 94 | BL46: =H46+M46+R46+W46+AB46+AL46+AQ46+AV46+BA46+BF46+BK46 -> 823.5 | BM46: =BL46/9 -> 91.5 | BQ46: 2 | BR46: 1 | BS46: 0
A47: 33 | H47: =(D47+E47+F47+G47)/3 -> 0 | M47: =(I47+J47+K47+L47)/3 -> 0 | R47: =(N47+O47+P47+Q47)/3 -> 0 | W47: =(S47+T47+U47+V47)/4 -> 0 | AB47: =(X47+Y47+Z47+AA47)/4 -> 0 | AG47: =(AC47+AD47+AE47+AF47)/4 -> 0 | AL47: =(AH47+AI47+AJ47+AK47)/3 -> 0 | AQ47: =(AM47+AN47+AO47+AP47)/3 -> 0 | AV47: =(AR47+AS47+AT47+AU47)/43 -> 0 | BA47: =(AW47+AX47+AY47+AZ47)/3 -> 0 | BF47: =(BB47+BC47+BD47+BE47)/3 -> 0 | BK47: =(BG47+BH47+BI47+BJ47)/3 -> 0 | BL47: =H47+M47+R47+W47+AB47+AL47+AQ47+AV47+BA47+BF47+BK47 -> 0 | BM47: =BL47/9 -> 0
A48: 34 | H48: =(D48+E48+F48+G48)/3 -> 0 | M48: =(I48+J48+K48+L48)/3 -> 0 | R48: =(N48+O48+P48+Q48)/3 -> 0 | W48: =(S48+T48+U48+V48)/4 -> 0 | AB48: =(X48+Y48+Z48+AA48)/4 -> 0 | AG48: =(AC48+AD48+AE48+AF48)/4 -> 0 | AL48: =(AH48+AI48+AJ48+AK48)/3 -> 0 | AQ48: =(AM48+AN48+AO48+AP48)/3 -> 0 | AV48: =(AR48+AS48+AT48+AU48)/43 -> 0 | BA48: =(AW48+AX48+AY48+AZ48)/3 -> 0 | BF48: =(BB48+BC48+BD48+BE48)/3 -> 0 | BK48: =(BG48+BH48+BI48+BJ48)/3 -> 0 | BL48: =H48+M48+R48+W48+AB48+AL48+AQ48+AV48+BA48+BF48+BK48 -> 0 | BM48: =BL48/9 -> 0
A49: 35 | H49: =(D49+E49+F49+G49)/3 -> 0 | M49: =(I49+J49+K49+L49)/3 -> 0 | R49: =(N49+O49+P49+Q49)/3 -> 0 | W49: =(S49+T49+U49+V49)/4 -> 0 | AB49: =(X49+Y49+Z49+AA49)/4 -> 0 | AG49: =(AC49+AD49+AE49+AF49)/4 -> 0 | AL49: =(AH49+AI49+AJ49+AK49)/3 -> 0 | AQ49: =(AM49+AN49+AO49+AP49)/3 -> 0 | AV49: =(AR49+AS49+AT49+AU49)/43 -> 0 | BA49: =(AW49+AX49+AY49+AZ49)/3 -> 0 | BF49: =(BB49+BC49+BD49+BE49)/3 -> 0 | BK49: =(BG49+BH49+BI49+BJ49)/3 -> 0 | BL49: =H49+M49+R49+W49+AB49+AL49+AQ49+AV49+BA49+BF49+BK49 -> 0 | BM49: =BL49/9 -> 0
A50: 36 | H50: =(D50+E50+F50+G50)/3 -> 0 | M50: =(I50+J50+K50+L50)/3 -> 0 | R50: =(N50+O50+P50+Q50)/3 -> 0 | W50: =(S50+T50+U50+V50)/4 -> 0 | AB50: =(X50+Y50+Z50+AA50)/4 -> 0 | AG50: =(AC50+AD50+AE50+AF50)/4 -> 0 | AL50: =(AH50+AI50+AJ50+AK50)/3 -> 0 | AQ50: =(AM50+AN50+AO50+AP50)/3 -> 0 | AV50: =(AR50+AS50+AT50+AU50)/43 -> 0 | BA50: =(AW50+AX50+AY50+AZ50)/3 -> 0 | BF50: =(BB50+BC50+BD50+BE50)/3 -> 0 | BK50: =(BG50+BH50+BI50+BJ50)/3 -> 0 | BL50: =H50+M50+R50+W50+AB50+AL50+AQ50+AV50+BA50+BF50+BK50 -> 0 | BM50: =BL50/9 -> 0
A51: 37 | H51: =(D51+E51+F51+G51)/3 -> 0 | M51: =(I51+J51+K51+L51)/3 -> 0 | R51: =(N51+O51+P51+Q51)/3 -> 0 | W51: =(S51+T51+U51+V51)/4 -> 0 | AB51: =(X51+Y51+Z51+AA51)/4 -> 0 | AG51: =(AC51+AD51+AE51+AF51)/4 -> 0 | AL51: =(AH51+AI51+AJ51+AK51)/3 -> 0 | AQ51: =(AM51+AN51+AO51+AP51)/3 -> 0 | AV51: =(AR51+AS51+AT51+AU51)/43 -> 0 | BA51: =(AW51+AX51+AY51+AZ51)/3 -> 0 | BF51: =(BB51+BC51+BD51+BE51)/3 -> 0 | BK51: =(BG51+BH51+BI51+BJ51)/3 -> 0 | BL51: =H51+M51+R51+W51+AB51+AL51+AQ51+AV51+BA51+BF51+BK51 -> 0 | BM51: =BL51/9 -> 0
A52: 38 | H52: =(D52+E52+F52+G52)/3 -> 0 | M52: =(I52+J52+K52+L52)/3 -> 0 | R52: =(N52+O52+P52+Q52)/3 -> 0 | W52: =(S52+T52+U52+V52)/4 -> 0 | AB52: =(X52+Y52+Z52+AA52)/4 -> 0 | AG52: =(AC52+AD52+AE52+AF52)/4 -> 0 | AL52: =(AH52+AI52+AJ52+AK52)/3 -> 0 | AQ52: =(AM52+AN52+AO52+AP52)/3 -> 0 | AV52: =(AR52+AS52+AT52+AU52)/43 -> 0 | BA52: =(AW52+AX52+AY52+AZ52)/3 -> 0 | BF52: =(BB52+BC52+BD52+BE52)/3 -> 0 | BK52: =(BG52+BH52+BI52+BJ52)/3 -> 0 | BL52: =H52+M52+R52+W52+AB52+AL52+AQ52+AV52+BA52+BF52+BK52 -> 0 | BM52: =BL52/9 -> 0
A53: 39 | H53: =(D53+E53+F53+G53)/3 -> 0 | M53: =(I53+J53+K53+L53)/3 -> 0 | R53: =(N53+O53+P53+Q53)/3 -> 0 | W53: =(S53+T53+U53+V53)/4 -> 0 | AB53: =(X53+Y53+Z53+AA53)/4 -> 0 | AG53: =(AC53+AD53+AE53+AF53)/4 -> 0 | AL53: =(AH53+AI53+AJ53+AK53)/3 -> 0 | AQ53: =(AM53+AN53+AO53+AP53)/3 -> 0 | AV53: =(AR53+AS53+AT53+AU53)/43 -> 0 | BA53: =(AW53+AX53+AY53+AZ53)/3 -> 0 | BF53: =(BB53+BC53+BD53+BE53)/3 -> 0 | BK53: =(BG53+BH53+BI53+BJ53)/3 -> 0 | BL53: =H53+M53+R53+W53+AB53+AL53+AQ53+AV53+BA53+BF53+BK53 -> 0 | BM53: =BL53/9 -> 0
A54: 40 | H54: =(D54+E54+F54+G54)/3 -> 0 | M54: =(I54+J54+K54+L54)/3 -> 0 | R54: =(N54+O54+P54+Q54)/3 -> 0 | W54: =(S54+T54+U54+V54)/4 -> 0 | AB54: =(X54+Y54+Z54+AA54)/4 -> 0 | AG54: =(AC54+AD54+AE54+AF54)/4 -> 0 | AL54: =(AH54+AI54+AJ54+AK54)/3 -> 0 | AQ54: =(AM54+AN54+AO54+AP54)/3 -> 0 | AV54: =(AR54+AS54+AT54+AU54)/43 -> 0 | BA54: =(AW54+AX54+AY54+AZ54)/3 -> 0 | BF54: =(BB54+BC54+BD54+BE54)/3 -> 0 | BK54: =(BG54+BH54+BI54+BJ54)/3 -> 0 | BL54: =H54+M54+R54+W54+AB54+AL54+AQ54+AV54+BA54+BF54+BK54 -> 0 | BM54: =BL54/9 -> 0
A55: 41 | H55: =(D55+E55+F55+G55)/3 -> 0 | M55: =(I55+J55+K55+L55)/3 -> 0 | R55: =(N55+O55+P55+Q55)/3 -> 0 | W55: =(S55+T55+U55+V55)/4 -> 0 | AB55: =(X55+Y55+Z55+AA55)/4 -> 0 | AG55: =(AC55+AD55+AE55+AF55)/4 -> 0 | AL55: =(AH55+AI55+AJ55+AK55)/3 -> 0 | AQ55: =(AM55+AN55+AO55+AP55)/3 -> 0 | AV55: =(AR55+AS55+AT55+AU55)/43 -> 0 | BA55: =(AW55+AX55+AY55+AZ55)/3 -> 0 | BF55: =(BB55+BC55+BD55+BE55)/3 -> 0 | BK55: =(BG55+BH55+BI55+BJ55)/3 -> 0 | BL55: =H55+M55+R55+W55+AB55+AL55+AQ55+AV55+BA55+BF55+BK55 -> 0 | BM55: =BL55/9 -> 0
A56: 42 | H56: =(D56+E56+F56+G56)/3 -> 0 | M56: =(I56+J56+K56+L56)/3 -> 0 | R56: =(N56+O56+P56+Q56)/3 -> 0 | W56: =(S56+T56+U56+V56)/4 -> 0 | AB56: =(X56+Y56+Z56+AA56)/4 -> 0 | AG56: =(AC56+AD56+AE56+AF56)/4 -> 0 | AL56: =(AH56+AI56+AJ56+AK56)/3 -> 0 | AQ56: =(AM56+AN56+AO56+AP56)/3 -> 0 | AV56: =(AR56+AS56+AT56+AU56)/43 -> 0 | BA56: =(AW56+AX56+AY56+AZ56)/3 -> 0 | BF56: =(BB56+BC56+BD56+BE56)/3 -> 0 | BK56: =(BG56+BH56+BI56+BJ56)/3 -> 0 | BL56: =H56+M56+R56+W56+AB56+AL56+AQ56+AV56+BA56+BF56+BK56 -> 0 | BM56: =BL56/9 -> 0
A57: 43 | H57: =(D57+E57+F57+G57)/3 -> 0 | M57: =(I57+J57+K57+L57)/3 -> 0 | R57: =(N57+O57+P57+Q57)/3 -> 0 | W57: =(S57+T57+U57+V57)/4 -> 0 | AB57: =(X57+Y57+Z57+AA57)/4 -> 0 | AG57: =(AC57+AD57+AE57+AF57)/4 -> 0 | AL57: =(AH57+AI57+AJ57+AK57)/3 -> 0 | AQ57: =(AM57+AN57+AO57+AP57)/3 -> 0 | AV57: =(AR57+AS57+AT57+AU57)/43 -> 0 | BA57: =(AW57+AX57+AY57+AZ57)/3 -> 0 | BF57: =(BB57+BC57+BD57+BE57)/3 -> 0 | BK57: =(BG57+BH57+BI57+BJ57)/3 -> 0 | BL57: =H57+M57+R57+W57+AB57+AL57+AQ57+AV57+BA57+BF57+BK57 -> 0 | BM57: =BL57/9 -> 0
A58: 44 | H58: =(D58+E58+F58+G58)/3 -> 0 | M58: =(I58+J58+K58+L58)/3 -> 0 | R58: =(N58+O58+P58+Q58)/3 -> 0 | W58: =(S58+T58+U58+V58)/4 -> 0 | AB58: =(X58+Y58+Z58+AA58)/4 -> 0 | AG58: =(AC58+AD58+AE58+AF58)/4 -> 0 | AL58: =(AH58+AI58+AJ58+AK58)/3 -> 0 | AQ58: =(AM58+AN58+AO58+AP58)/3 -> 0 | AV58: =(AR58+AS58+AT58+AU58)/43 -> 0 | BA58: =(AW58+AX58+AY58+AZ58)/3 -> 0 | BF58: =(BB58+BC58+BD58+BE58)/3 -> 0 | BK58: =(BG58+BH58+BI58+BJ58)/3 -> 0 | BL58: =H58+M58+R58+W58+AB58+AL58+AQ58+AV58+BA58+BF58+BK58 -> 0 | BM58: =BL58/9 -> 0
A59: 45 | H59: =(D59+E59+F59+G59)/3 -> 0 | M59: =(I59+J59+K59+L59)/3 -> 0 | R59: =(N59+O59+P59+Q59)/3 -> 0 | W59: =(S59+T59+U59+V59)/4 -> 0 | AB59: =(X59+Y59+Z59+AA59)/4 -> 0 | AG59: =(AC59+AD59+AE59+AF59)/4 -> 0 | AL59: =(AH59+AI59+AJ59+AK59)/3 -> 0 | AQ59: =(AM59+AN59+AO59+AP59)/3 -> 0 | AV59: =(AR59+AS59+AT59+AU59)/43 -> 0 | BA59: =(AW59+AX59+AY59+AZ59)/3 -> 0 | BF59: =(BB59+BC59+BD59+BE59)/3 -> 0 | BK59: =(BG59+BH59+BI59+BJ59)/3 -> 0 | BL59: =H59+M59+R59+W59+AB59+AL59+AQ59+AV59+BA59+BF59+BK59 -> 0 | BM59: =BL59/9 -> 0

Sheet CATATAN WALAS
A2: PERIODE SEMESTER GANJIL TAHUN PELAJARAN 2024/2025
A3: SMK YAJ
B5: KELAS | C5: ='LEGGER XII AKL'!C5 -> XII AKL
B6: JUMLAH SISWA | C6: ='LEGGER XII AKL'!I5 -> 32
B7: NAMA WALI KELAS | C7: ='LEGGER XII AKL'!I6 -> Elsa Wahyuningrum, A.Md. KA.
B8: NIP | C8: -
A10: 1 | B10: 2 | C10: 3 | D10: 4 | E10: 5 | F10: 6
A12: NO | B12: NAMA SISWA | C12: N I S N | D12: RATA-RATA NILAI | E12: PERINGKAT KELAS | F12: Catatan
A15: 1 | B15: ='LEGGER XII AKL'!B15 -> Amelia | C15: ='LEGGER XII AKL'!C15 -> 0068552301 | D15: ='LEGGER XII AKL'!BM15 -> 85.148148 | E15: =RANK(D15,D$15:D$59) -> 32 | F15: Jangan menyerah, tingkatkan kembali belajarmu
A16: 2 | B16: ='LEGGER XII AKL'!B16 -> Chrycen Rivia Disa | C16: ='LEGGER XII AKL'!C16 -> 0076793345 | D16: ='LEGGER XII AKL'!BM16 -> 91.925926 | E16: =RANK(D16,D$15:D$59) -> 12 | F16: Tingkatkan kembali belajarmu
A17: 3 | B17: ='LEGGER XII AKL'!B17 -> Citra Attailah | C17: ='LEGGER XII AKL'!C17 -> 0075546309 | D17: ='LEGGER XII AKL'!BM17 -> 92.12963 | E17: =RANK(D17,D$15:D$59) -> 11 | F17: Tingkatkan kembali belajarmu
A18: 4 | B18: ='LEGGER XII AKL'!B18 -> Dimas Setiawan | C18: ='LEGGER XII AKL'!C18 -> 0073521089 | D18: ='LEGGER XII AKL'!BM18 -> 91.203704 | E18: =RANK(D18,D$15:D$59) -> 19 | F18: Tingkatkan kembali belajarmu
A19: 5 | B19: ='LEGGER XII AKL'!B19 -> Fadhil Ubaidillah | C19: ='LEGGER XII AKL'!C19 -> 0063430650 | D19: ='LEGGER XII AKL'!BM19 -> 93.240741 | E19: =RANK(D19,D$15:D$59) -> 6 | F19: Prestasimu sudah cukup baik, tetapi tingkatkan belajarmu
A20: 6 | B20: ='LEGGER XII AKL'!B20 -> Ferza Febriansyah | C20: ='LEGGER XII AKL'!C20 -> 0071685041 | D20: ='LEGGER XII AKL'!BM20 -> 94.555556 | E20: =RANK(D20,D$15:D$59) -> 1 | F20: Pertahankan peringkat pertamamu untuk pembelajaran semester ini
A21: 7 | B21: ='LEGGER XII AKL'!B21 -> Iqlimah Cahaya Mustika | C21: ='LEGGER XII AKL'!C21 -> 0064268039 | D21: ='LEGGER XII AKL'!BM21 -> 89.074074 | E21: =RANK(D21,D$15:D$59) -> 30 | F21: Jangan menyerah, tingkatkan kembali belajarmu
A22: 8 | B22: ='LEGGER XII AKL'!B22 -> Irshal Rhama Aidillah | C22: ='LEGGER XII AKL'!C22 -> 3074487136 | D22: ='LEGGER XII AKL'!BM22 -> 91.814815 | E22: =RANK(D22,D$15:D$59) -> 13 | F22: Tingkatkan kembali belajarmu
A23: 9 | B23: ='LEGGER XII AKL'!B23 -> Jingga Nur Qalam | C23: ='LEGGER XII AKL'!C23 -> 0067481076 | D23: ='LEGGER XII AKL'!BM23 -> 91.277778 | E23: =RANK(D23,D$15:D$59) -> 17 | F23: Tingkatkan kembali belajarmu
A24: 10 | B24: ='LEGGER XII AKL'!B24 -> Karina Dwi Sagita | C24: ='LEGGER XII AKL'!C24 -> 0057659388 | D24: ='LEGGER XII AKL'!BM24 -> 89.37037 | E24: =RANK(D24,D$15:D$59) -> 29 | F24: Jangan menyerah, tingkatkan kembali belajarmu
A25: 11 | B25: ='LEGGER XII AKL'!B25 -> Larasati | C25: ='LEGGER XII AKL'!C25 -> 3073371186 | D25: ='LEGGER XII AKL'!BM25 -> 88.888889 | E25: =RANK(D25,D$15:D$59) -> 31 | F25: Jangan menyerah, tingkatkan kembali belajarmu
A26: 12 | B26: ='LEGGER XII AKL'!B26 -> Lia Apriyani | C26: ='LEGGER XII AKL'!C26 -> 0074403542 | D26: ='LEGGER XII AKL'!BM26 -> 91.481481 | E26: =RANK(D26,D$15:D$59) -> 16 | F26: Tingkatkan kembali belajarmu
... A46: 32 | B46: ='LEGGER XII AKL'!B46 -> Zafira Raysa Umar | C46: ='LEGGER XII AKL'!C46 -> 0073130066 | D46: ='LEGGER XII AKL'!BM46 -> 91.5 | E46: =RANK(D46,D$15:D$59) -> 15 | F46: Tingkatkan kembali belajarmu
A47: 33 | B47: ='LEGGER XII AKL'!B47 -> 0 | C47: ='LEGGER XII AKL'!C47 -> 0 | D47: ='LEGGER XII AKL'!BM47 -> 0
A48: 34 | B48: ='LEGGER XII AKL'!B48 -> 0 | C48: ='LEGGER XII AKL'!C48 -> 0 | D48: ='LEGGER XII AKL'!BM48 -> 0
A49: 35 | B49: ='LEGGER XII AKL'!B49 -> 0 | C49: ='LEGGER XII AKL'!C49 -> 0 | D49: ='LEGGER XII AKL'!BM49 -> 0
A50: 36 | B50: ='LEGGER XII AKL'!B50 -> 0 | C50: ='LEGGER XII AKL'!C50 -> 0 | D50: ='LEGGER XII AKL'!BM50 -> 0
A51: 37 | B51: ='LEGGER XII AKL'!B51 -> 0 | C51: ='LEGGER XII AKL'!C51 -> 0 | D51: ='LEGGER XII AKL'!BM51 -> 0
A52: 38 | B52: ='LEGGER XII AKL'!B52 -> 0 | C52: ='LEGGER XII AKL'!C52 -> 0 | D52: ='LEGGER XII AKL'!BM52 -> 0
A53: 39 | B53: ='LEGGER XII AKL'!B53 -> 0 | C53: ='LEGGER XII AKL'!C53 -> 0 | D53: ='LEGGER XII AKL'!BM53 -> 0
A54: 40 | B54: ='LEGGER XII AKL'!B54 -> 0 | C54: ='LEGGER XII AKL'!C54 -> 0 | D54: ='LEGGER XII AKL'!BM54 -> 0
A55: 41 | B55: ='LEGGER XII AKL'!B55 -> 0 | C55: ='LEGGER XII AKL'!C55 -> 0 | D55: ='LEGGER XII AKL'!BM55 -> 0
A56: 42 | B56: ='LEGGER XII AKL'!B56 -> 0 | C56: ='LEGGER XII AKL'!C56 -> 0 | D56: ='LEGGER XII AKL'!BM56 -> 0
A57: 43 | B57: ='LEGGER XII AKL'!B57 -> 0 | C57: ='LEGGER XII AKL'!C57 -> 0 | D57: ='LEGGER XII AKL'!BM57 -> 0
A58: 44 | B58: ='LEGGER XII AKL'!B58 -> 0 | C58: ='LEGGER XII AKL'!C58 -> 0 | D58: ='LEGGER XII AKL'!BM58 -> 0
A59: 45 | B59: ='LEGGER XII AKL'!B59 -> 0 | C59: ='LEGGER XII AKL'!C59 -> 0 | D59: ='LEGGER XII AKL'!BM59 -> 0

Sheet PKL
A2: INPUT REKAM DATA PELAKSANAAN DAN HASIL PRAKERIN
A3: PERIODE SEMESTER GANJIL TAHUN PELAJARAN 2021/2022
A4: SMK NEGERI 1 DEPOK
B6: KELAS : | C6: ='LEGGER XII AKL'!C6 -> 1 (SATU)
B7: JUMLAH SISWA : | C7: ='LEGGER XII AKL'!C7 -> 2024 /2025
B8: NAMA WALI KELAS : | C8: ='LEGGER XII AKL'!I6 -> Elsa Wahyuningrum, A.Md. KA.
B9: NIP / NUPTK : | C9: ='LEGGER XII AKL'!I7 -> -
A11: 1 | B11: 2 | C11: 3 | D11: 4 | E11: 5 | F11: 6 | G11: 7 | H11: 8 | I11: 9 | J11: 10 | K11: 11 | L11: 12 | M11: 13 | N11: 14 | O11: 15
A13: NO | B13: NAMA SISWA | C13: N I S N | D13: PRAKERIN / PKL / MAGANG
D14: PRAKERIN / MAGANG 1 | H14: PRAKERIN / MAGANG 2 | L14: PRAKERIN / MAGANG 3
D15: Nama DU/DI 1 | E15: Lokasi 1 | F15: Lamanya 1 | G15: Keterangan 1 | H15: Nama DU/DI 2 | I15: Lokasi 2 | J15: Lamanya 2 | K15: Keterangan 2 | L15: Nama DU/DI 3 | M15: Lokasi 3 | N15: Lamanya 3 | O15: Keterangan 3
A16: 1 | B16: ='LEGGER XII AKL'!B15 -> Amelia | C16: ='LEGGER XII AKL'!C15 -> 0068552301 | D16: - | E16: - | F16: - | G16: - | H16: - | I16: - | J16: - | K16: - | L16: - | M16: - | N16: - | O16: -
A17: 2 | B17: ='LEGGER XII AKL'!B16 -> Chrycen Rivia Disa | C17: ='LEGGER XII AKL'!C16 -> 0076793345 | D17: - | E17: - | F17: - | G17: - | H17: - | I17: - | J17: - | K17: - | L17: - | M17: - | N17: - | O17: -
A18: 3 | B18: ='LEGGER XII AKL'!B17 -> Citra Attailah | C18: ='LEGGER XII AKL'!C17 -> 0075546309 | D18: - | E18: - | F18: - | G18: - | H18: - | I18: - | J18: - | K18: - | L18: - | M18: - | N18: - | O18: -
A19: 4 | B19: ='LEGGER XII AKL'!B18 -> Dimas Setiawan | C19: ='LEGGER XII AKL'!C18 -> 0073521089 | D19: - | E19: - | F19: - | G19: - | H19: - | I19: - | J19: - | K19: - | L19: - | M19: - | N19: - | O19: -
A20: 5 | B20: ='LEGGER XII AKL'!B19 -> Fadhil Ubaidillah | C20: ='LEGGER XII AKL'!C19 -> 0063430650 | D20: - | E20: - | F20: - | G20: - | H20: - | I20: - | J20: - | K20: - | L20: - | M20: - | N20: - | O20: -
A21: 6 | B21: ='LEGGER XII AKL'!B20 -> Ferza Febriansyah | C21: ='LEGGER XII AKL'!C20 -> 0071685041 | D21: - | E21: - | F21: - | G21: - | H21: - | I21: - | J21: - | K21: - | L21: - | M21: - | N21: - | O21: -
A22: 7 | B22: ='LEGGER XII AKL'!B21 -> Iqlimah Cahaya Mustika | C22: ='LEGGER XII AKL'!C21 -> 0064268039 | D22: - | E22: - | F22: - | G22: - | H22: - | I22: - | J22: - | K22: - | L22: - | M22: - | N22: - | O22: -
A23: 8 | B23: ='LEGGER XII AKL'!B22 -> Irshal Rhama Aidillah | C23: ='LEGGER XII AKL'!C22 -> 3074487136 | D23: - | E23: - | F23: - | G23: - | H23: - | I23: - | J23: - | K23: - | L23: - | M23: - | N23: - | O23: -
A24: 9 | B24: ='LEGGER XII AKL'!B23 -> Jingga Nur Qalam | C24: ='LEGGER XII AKL'!C23 -> 0067481076 | D24: - | E24: - | F24: - | G24: - | H24: - | I24: - | J24: - | K24: - | L24: - | M24: - | N24: - | O24: -
A25: 10 | B25: ='LEGGER XII AKL'!B24 -> Karina Dwi Sagita | C25: ='LEGGER XII AKL'!C24 -> 0057659388 | D25: - | E25: - | F25: - | G25: - | H25: - | I25: - | J25: - | K25: - | L25: - | M25: - | N25: - | O25: -
A26: 11 | B26: ='LEGGER XII AKL'!B25 -> Larasati | C26: ='LEGGER XII AKL'!C25 -> 3073371186 | D26: - | E26: - | F26: - | G26: - | H26: - | I26: - | J26: - | K26: - | L26: - | M26: - | N26: - | O26: -
A27: 12 | B27: ='LEGGER XII AKL'!B26 -> Lia Apriyani | C27: ='LEGGER XII AKL'!C26 -> 0074403542 | D27: - | E27: - | F27: - | G27: - | H27: - | I27: - | J27: - | K27: - | L27: - | M27: - | N27: - | O27: -
... A55: 40 | B55: ='LEGGER XII AKL'!B54 -> 0 | C55: ='LEGGER XII AKL'!C54 -> 0 | D55: - | E55: - | F55: - | G55: - | H55: - | I55: - | J55: - | K55: - | L55: - | M55: - | N55: - | O55: -

Sheet EKSKUL
A2: INPUT REKAM DATA PELAKSANAAN DAN HASIL EKSTRA KULIKULER
A3: PERIODE SEMESTER GANJIL TAHUN PELAJARAN 2024/2025
A4: SMK YAJ
B6: KELAS : | C6: ='LEGGER XII AKL'!C5 -> XII AKL
B7: JUMLAH SISWA : | C7: ='LEGGER XII AKL'!I5&" SISWA" -> 32 SISWA
B8: NAMA WALI KELAS : | C8: ='LEGGER XII AKL'!I6 -> Elsa Wahyuningrum, A.Md. KA.
B9: NIP / NUPTK : | C9: ='LEGGER XII AKL'!I7 -> -
A11: 1 | B11: 2 | C11: 3 | D11: 4 | E11: 5 | F11: 6 | G11: 7 | H11: 8 | I11: 9 | J11: 10 | K11: 11 | L11: 12 | M11: 13 | N11: 14 | O11: 15
A13: NO | B13: NAMA SISWA | C13: N I S N | D13: EKSTRAKURIKULER
D14: EKSTRAKURIKULER 1 | H14: EKSTRAKURIKULER 2 | L14: EKSTRAKURIKULER 3
D15: Nama Ekskul 1 | E15: Angka 1 | F15: Huruf 1 | G15: Keterangan 1 | H15: Nama Ekskul 2 | I15: Angka 2 | J15: Huruf 2 | K15: Keterangan 2 | L15: Nama Ekskul 3 | M15: Angka 3 | N15: Huruf 3 | O15: Keterangan 3
A16: 1 | B16: ='LEGGER XII AKL'!B15 -> Amelia | C16: ='LEGGER XII AKL'!C15 -> 0068552301 | D16: - | E16: - | F16: - | G16: - | H16: - | I16: - | J16: - | K16: - | L16: - | M16: - | N16: - | O16: -
A17: 2 | B17: ='LEGGER XII AKL'!B16 -> Chrycen Rivia Disa | C17: ='LEGGER XII AKL'!C16 -> 0076793345 | D17: - | E17: - | F17: - | G17: - | H17: - | I17: - | J17: - | K17: - | L17: - | M17: - | N17: - | O17: -
A18: 3 | B18: ='LEGGER XII AKL'!B17 -> Citra Attailah | C18: ='LEGGER XII AKL'!C17 -> 0075546309 | D18: - | E18: - | F18: - | G18: - | H18: - | I18: - | J18: - | K18: - | L18: - | M18: - | N18: - | O18: -
A19: 4 | B19: ='LEGGER XII AKL'!B18 -> Dimas Setiawan | C19: ='LEGGER XII AKL'!C18 -> 0073521089 | D19: - | E19: - | F19: - | G19: - | H19: - | I19: - | J19: - | K19: - | L19: - | M19: - | N19: - | O19: -
A20: 5 | B20: ='LEGGER XII AKL'!B19 -> Fadhil Ubaidillah | C20: ='LEGGER XII AKL'!C19 -> 0063430650 | D20: - | E20: - | F20: - | G20: - | H20: - | I20: - | J20: - | K20: - | L20: - | M20: - | N20: - | O20: -
A21: 6 | B21: ='LEGGER XII AKL'!B20 -> Ferza Febriansyah | C21: ='LEGGER XII AKL'!C20 -> 0071685041 | D21: - | E21: - | F21: - | G21: - | H21: - | I21: - | J21: - | K21: - | L21: - | M21: - | N21: - | O21: -
A22: 7 | B22: ='LEGGER XII AKL'!B21 -> Iqlimah Cahaya Mustika | C22: ='LEGGER XII AKL'!C21 -> 0064268039 | D22: - | E22: - | F22: - | G22: - | H22: - | I22: - | J22: - | K22: - | L22: - | M22: - | N22: - | O22: -
A23: 8 | B23: ='LEGGER XII AKL'!B22 -> Irshal Rhama Aidillah | C23: ='LEGGER XII AKL'!C22 -> 3074487136 | D23: - | E23: - | F23: - | G23: - | H23: - | I23: - | J23: - | K23: - | L23: - | M23: - | N23: - | O23: -
A24: 9 | B24: ='LEGGER XII AKL'!B23 -> Jingga Nur Qalam | C24: ='LEGGER XII AKL'!C23 -> 0067481076 | D24: - | E24: - | F24: - | G24: - | H24: - | I24: - | J24: - | K24: - | L24: - | M24: - | N24: - | O24: -
A25: 10 | B25: ='LEGGER XII AKL'!B24 -> Karina Dwi Sagita | C25: ='LEGGER XII AKL'!C24 -> 0057659388 | D25: - | E25: - | F25: - | G25: - | H25: - | I25: - | J25: - | K25: - | L25: - | M25: - | N25: - | O25: -
A26: 11 | B26: ='LEGGER XII AKL'!B25 -> Larasati | C26: ='LEGGER XII AKL'!C25 -> 3073371186 | D26: - | E26: - | F26: - | G26: - | H26: - | I26: - | J26: - | K26: - | L26: - | M26: - | N26: - | O26: -
A27: 12 | B27: ='LEGGER XII AKL'!B26 -> Lia Apriyani | C27: ='LEGGER XII AKL'!C26 -> 0074403542 | D27: - | E27: - | F27: - | G27: - | H27: - | I27: - | J27: - | K27: - | L27: - | M27: - | N27: - | O27: -
... A60: 45 | B60: ='LEGGER XII AKL'!B59 -> 0 | C60: ='LEGGER XII AKL'!C59 -> 0 | D60: - | E60: - | F60: - | G60: - | H60: - | I60: - | J60: - | K60: - | L60: - | M60: - | N60: - | O60: -

Sheet DESKRIPSI
A2: DESKRIPSI CAPAIAN KOMPETENSI PESERTA DIDIK | F2: Konsep diisi : indikator kemampuan siswa
A3: PERIODE SEMESTER GANJIL TAHUN PELAJARAN 2024/2025
A4: SMK YAJ
B6: 1 | C6: 2 | D6: 3 | E6: 4 | F6: 5 | G6: 6 | H6: 7 | I6: 8 | J6: 9 | K6: 10 | L6: 11 | M6: 12 | N6: 13 | O6: 14
A8: No | B8: Nilai | C8: Kualifikasi | D8: Kelompok Umum #1 | E8: Kelompok Umum #2 | F8: Kelompok Umum #3 | G8: Kelompok Umum #4 | H8: Kelompok Umum #5 | I8: Kelompok Umum #6 | J8: Kelompok Kejuruan #7 | K8: Kelompok Kejuruan #8 | L8: Kelompok Kejuruan #9 | M8: Kelompok Kejuruan #10 | N8: Kelompok Kejuruan #11 | O8: Muatan Lokal #12
D9: ='RAPORT XIIAKL '!C14 -> Pendidikan Agama dan Budi Pekerti | E9: ='RAPORT XIIAKL '!C15 -> Pendidikan Pancasila | F9: ='RAPORT XIIAKL '!C16 -> Bahasa Indonesia | G9: ='RAPORT XIIAKL '!C17 -> Pendidikan Jasmani, Olahraga dan Kesehatan | H9: ='RAPORT XIIAKL '!C18 -> Sejarah | I9: ='RAPORT XIIAKL '!C19 -> Seni Budaya | J9: ='RAPORT XIIAKL '!C21 -> Matematika | K9: ='RAPORT XIIAKL '!C22 -> Bahasa Inggris | L9: ='RAPORT XIIAKL '!C23 -> Konsentrasi Keahlian | M9: ='RAPORT XIIAKL '!C24 -> Projek Kreatif dan Kewirausahaan | N9: ='RAPORT XIIAKL '!C25 -> Mata Pelajaran Pilhan (Spreadsheet) | O9: ='RAPORT XIIAKL '!C27 -> Dasar Design Grafis
A10: 1 | B10: 90 - 100 | C10: Sangat Baik | D10: Peserta didik Mampu membaca, menghafal Q.S. Al-Baqarah/2: 155-156 dan mampu mempraktekkan Da’wah (Ceramah, Pidato, Khutbah), dzikir dan do’a setelah shalat Fardhu, serta tahlil dengan lancar dan Sangat Baik. | E10: Peserta didik mampu menjelaskan peran dan kewajiban warga negara Indonesia dalam menjaga persatuan dan kesatuan bangsa dengan Sangat Baik. | F10: Peserta didik mampu menerapkan etika berkomunikasi secara lisan dan tulisan, integritas antara lain; jujur, disiplin, kemandirian dan tanggung jawab, etos kerja secara mandiri dan secara tim. Kependudukan sosial dan lingkungan, serta ketaatan terhadap norma, K3LH dan POS juga berlaku di dunia kerja dengan Sangat Baik. | G10: Konsep _ PENJAS _ Sangat Kompeten | H10: Konsep _ SEJARAH _ Sangat Kompeten | I10: Konsep _ SENI _ Sangat Kompeten | J10: Peserta didik mampu memahami konsep peluang menggunakan Kaidah Pencacahan (Pengisian Tempat, Faktorial, Permutasi dan Kombinasi dengan Sangat Baik. | K10: Peserta didik mampu menulis Surat lamaran kerja dan daftar riwayat hidup dalam Bahasa inggris secara benar dengan Sangat Baik. | L10: Peserta didik mampu menganalisis perhitungan persediaan dengan berbagai metode, menganalisis rekonsiliasi bank, mampu menghitung PPh Pasal 21 terutang dan mampu memahami siklus akuntansi lembaga pemerintahan. Peserta didik mampu mencatat transaksi serta memposting ke dalam Jurnal Umum, Buku Besar, dan Neraca Saldo pada Perusahaan Jasa dengan Sangat Baik. | M10: Peserta didik mampu membaca peluang usaha dengan mengidentifikasi potensi yang ada di lingkungan internal dan eksternal SMK serta menetapkan jenis usaha, memasarkan produk dengan menentukan segmen pasar, menentukan harga produk, dan menentukan media yang digunakan untuk memasarkan produk dengan Sangat Baik. | N10: Peserta didik mampu membuat bukti transaksi pada Perusahaan Jasa dengan Sangat Baik. | O10: Peserta didik mampu menerapkan penggunaan layer untuk pengelolaan objek dalam desain dengan Sangat Baik.
A11: 2 | B11: 80 - 89 | C11: Baik | D11: Peserta didik Mampu membaca, menghafal Q.S. Al-Baqarah/2: 155-156 dan mampu mempraktekkan Da’wah (Ceramah, Pidato, Khutbah), dzikir dan do’a setelah shalat Fardhu, serta tahlil dengan Baik. | E11: Peserta didik mampu menjelaskan peran dan kewajiban warga negara Indonesia dalam menjaga persatuan dan kesatuan bangsa dengan Baik. | F11: Peserta didik mampu menerapkan etika berkomunikasi secara lisan dan tulisan, integritas antara lain; jujur, disiplin, kemandirian dan tanggung jawab, etos kerja secara mandiri dan secara tim. Kependudukan sosial dan lingkungan, serta ketaatan terhadap norma, K3LH dan POS juga berlaku di dunia kerja dengan Baik. | G11: Konsep _ PENJAS _ Kompeten | H11: Konsep _ SEJARAH _ Kompeten | I11: Konsep _ SENI _ Kompeten | J11: Peserta didik mampu memahami konsep peluang menggunakan Kaidah Pencacahan (Pengisian Tempat, Faktorial, Permutasi dan Kombinasi dengan Baik. | K11: Peserta didik mampu menulis Surat lamaran kerja dan daftar riwayat hidup dalam Bahasa inggris secara benar dengan Baik. | L11: Peserta didik mampu menganalisis perhitungan persediaan dengan berbagai metode, menganalisis rekonsiliasi bank, mampu menghitung PPh Pasal 21 terutang dan mampu memahami siklus akuntansi lembaga pemerintahan. Peserta didik mampu mencatat transaksi serta memposting ke dalam Jurnal Umum, Buku Besar, dan Neraca Saldo pada Perusahaan Jasa dengan Baik. | M11: Peserta didik mampu membaca peluang usaha dengan mengidentifikasi potensi yang ada di lingkungan internal dan eksternal SMK serta menetapkan jenis usaha, memasarkan produk dengan menentukan segmen pasar, menentukan harga produk, dan menentukan media yang digunakan untuk memasarkan produk dengan Baik. | N11: Peserta didik mampu membuat bukti transaksi pada Perusahaan Jasa dengan Baik. | O11: Peserta didik mampu menerapkan penggunaan layer untuk pengelolaan objek dalam desain dengan Baik.
A12: 3 | B12: 70 - 79 | C12: Cukup | D12: Peserta didik Mampu membaca, menghafal Q.S. Al-Baqarah/2: 155-156 dan mampu mempraktekkan Da’wah (Ceramah, Pidato, Khutbah), dzikir dan do’a setelah shalat Fardhu, serta tahlil dengan Cukup Baik. | E12: Peserta didik mampu menjelaskan peran dan kewajiban warga negara Indonesia dalam menjaga persatuan dan kesatuan bangsa dengan Cukup Baik. | F12: Peserta didik mampu menerapkan etika berkomunikasi secara lisan dan tulisan, integritas antara lain; jujur, disiplin, kemandirian dan tanggung jawab, etos kerja secara mandiri dan secara tim. Kependudukan sosial dan lingkungan, serta ketaatan terhadap norma, K3LH dan POS juga berlaku di dunia kerja dengan Cukup Baik. | G12: Konsep _ PENJAS _ Cukup Kompeten | H12: Konsep _ SEJARAH _ Cukup Kompeten | I12: Konsep _ SENI _ Cukup Kompeten | J12: Peserta didik mampu memahami konsep peluang menggunakan Kaidah Pencacahan (Pengisian Tempat, Faktorial, Permutasi dan Kombinasi dengan Cukup Baik. | K12: Peserta didik mampu menulis Surat lamaran kerja dan daftar riwayat hidup dalam Bahasa inggris secara benar dengan Cukup Baik. | L12: Peserta didik mampu menganalisis perhitungan persediaan dengan berbagai metode, menganalisis rekonsiliasi bank, mampu menghitung PPh Pasal 21 terutang dan mampu memahami siklus akuntansi lembaga pemerintahan. Peserta didik mampu mencatat transaksi serta memposting ke dalam Jurnal Umum, Buku Besar, dan Neraca Saldo pada Perusahaan Jasa dengan Cukup Baik. | M12: Peserta didik mampu membaca peluang usaha dengan mengidentifikasi potensi yang ada di lingkungan internal dan eksternal SMK serta menetapkan jenis usaha, memasarkan produk dengan menentukan segmen pasar, menentukan harga produk, dan menentukan media yang digunakan untuk memasarkan produk dengan Cukup Baik. | N12: Peserta didik mampu membuat bukti transaksi pada Perusahaan Jasa dengan Cukup Baik. | O12: Peserta didik mampu menerapkan penggunaan layer untuk pengelolaan objek dalam desain dengan Cukup Baik.
A13: 4 | B13: 0 - 69 | C13: Perlu Bimbingan | D13: Peserta didik belum Mampu membaca, menghafal Q.S. Al-Baqarah/2: 155-156 dan belum mampu mempraktekkan Da’wah (Ceramah, Pidato, Khutbah), dzikir dan do’a setelah shalat Fardhu, serta tahlil dengan Perlu Bimbingan | E13: Peserta didik belum mampu menjelaskan peran dan kewajiban warga negara Indonesia dalam menjaga persatuan dan kesatuan bangsa dengan Perlu Bimbingan. | F13: Peserta didik belum mampu menerapkan etika berkomunikasi secara lisan dan tulisan, integritas antara lain; jujur, disiplin, kemandirian dan tanggung jawab, etos kerja secara mandiri dan secara tim. Kependudukan sosial dan lingkungan, serta ketaatan terhadap norma, K3LH dan POS juga berlaku di dunia kerja dengan Perlu Bimbingan. | G13: Konsep _ PENJAS _ Belum Kompeten | H13: Konsep _ SEJARAH _ Belum Kompeten | I13: Konsep _ SENI _ Belum Kompeten | J13: Peserta didik belum mampu memahami konsep peluang menggunakan Kaidah Pencacahan (Pengisian Tempat, Faktorial, Permutasi dan Kombinasi dengan Perlu Bimbingan. | K13: Peserta didik belum mampu menulis Surat lamaran kerja dan daftar riwayat hidup dalam Bahasa inggris secara benar dengan Perlu Bimbingan. | L13: Peserta didik belum mampu menganalisis perhitungan persediaan dengan berbagai metode, menganalisis rekonsiliasi bank, mampu menghitung PPh Pasal 21 terutang dan mampu memahami siklus akuntansi lembaga pemerintahan. Peserta didik mampu mencatat transaksi serta memposting ke dalam Jurnal Umum, Buku Besar, Neraca Saldo pada Perusahaan Jasa dan Perlu Bimbingan. | M13: Peserta didik belum mampu membaca peluang usaha dengan mengidentifikasi potensi yang ada di lingkungan internal dan eksternal SMK serta menetapkan jenis usaha, memasarkan produk dengan menentukan segmen pasar, menentukan harga produk, dan menentukan media yang digunakan untuk memasarkan produk dengan Perlu Bimbingan. | N13: Peserta didik belum mampu membuat bukti transaksi pada Perusahaan Jasa dan Perlu Bimbingan | O13: Peserta didik belum mampu menerapkan penggunaan layer untuk pengelolaan objek dalam desain dan Perlu Bimbingan.

Sheet PRESTASI
A2: INPUT REKAM DATA PELAKSANAAN DAN HASIL PRESTASI SISWA
A3: PERIODE SEMESTER GANJIL TAHUN PELAJARAN 2021/2022
A4: SMK NEGERI 1 DEPOK
B6: KELAS : | C6: ='LEGGER XII AKL'!C6 -> 1 (SATU)
B7: JUMLAH SISWA : | C7: ='LEGGER XII AKL'!C7 -> 2024 /2025
B8: NAMA WALI KELAS : | C8: ='LEGGER XII AKL'!I6 -> Elsa Wahyuningrum, A.Md. KA.
B9: NIP / NUPTK : | C9: ='LEGGER XII AKL'!I7 -> -
A11: 1 | B11: 2 | C11: 3 | D11: 4 | E11: 5 | F11: 6 | G11: 7 | H11: 8 | I11: 9 | J11: 10 | K11: 11 | L11: 12 | M11: 13 | N11: 14 | O11: 15
A13: NO | B13: NAMA SISWA | C13: N I S N | D13: PRESTASI / KEJUARAAN / MENANG LOMBA
D14: KEJUARAAN 1 | H14: KEJUARAAN 2 | L14: KEJUARAAN 3
D15: Nama Lomba 1 | E15: Tingkat 1 | F15: Raih 1 | G15: Keterangan 1 | H15: Nama Lomba 2 | I15: Tingkat 2 | J15: Raih 2 | K15: Keterangan 2 | L15: Nama Lomba 3 | M15: Tingkat 3 | N15: Raih 3 | O15: Keterangan 3
A16: 1 | B16: ='LEGGER XII AKL'!B15 -> Amelia | C16: ='LEGGER XII AKL'!C15 -> 0068552301 | D16: - | E16: - | F16: - | G16: - | H16: - | I16: - | J16: - | K16: - | L16: - | M16: - | N16: - | O16: -
A17: 2 | B17: ='LEGGER XII AKL'!B16 -> Chrycen Rivia Disa | C17: ='LEGGER XII AKL'!C16 -> 0076793345 | D17: - | E17: - | F17: - | G17: - | H17: - | I17: - | J17: - | K17: - | L17: - | M17: - | N17: - | O17: -
A18: 3 | B18: ='LEGGER XII AKL'!B17 -> Citra Attailah | C18: ='LEGGER XII AKL'!C17 -> 0075546309 | D18: - | E18: - | F18: - | G18: - | H18: - | I18: - | J18: - | K18: - | L18: - | M18: - | N18: - | O18: -
A19: 4 | B19: ='LEGGER XII AKL'!B18 -> Dimas Setiawan | C19: ='LEGGER XII AKL'!C18 -> 0073521089 | D19: - | E19: - | F19: - | G19: - | H19: - | I19: - | J19: - | K19: - | L19: - | M19: - | N19: - | O19: -
A20: 5 | B20: ='LEGGER XII AKL'!B19 -> Fadhil Ubaidillah | C20: ='LEGGER XII AKL'!C19 -> 0063430650 | D20: - | E20: - | F20: - | G20: - | H20: - | I20: - | J20: - | K20: - | L20: - | M20: - | N20: - | O20: -
A21: 6 | B21: ='LEGGER XII AKL'!B20 -> Ferza Febriansyah | C21: ='LEGGER XII AKL'!C20 -> 0071685041 | D21: - | E21: - | F21: - | G21: - | H21: - | I21: - | J21: - | K21: - | L21: - | M21: - | N21: - | O21: -
A22: 7 | B22: ='LEGGER XII AKL'!B21 -> Iqlimah Cahaya Mustika | C22: ='LEGGER XII AKL'!C21 -> 0064268039 | D22: - | E22: - | F22: - | G22: - | H22: - | I22: - | J22: - | K22: - | L22: - | M22: - | N22: - | O22: -
A23: 8 | B23: ='LEGGER XII AKL'!B22 -> Irshal Rhama Aidillah | C23: ='LEGGER XII AKL'!C22 -> 3074487136 | D23: - | E23: - | F23: - | G23: - | H23: - | I23: - | J23: - | K23: - | L23: - | M23: - | N23: - | O23: -
A24: 9 | B24: ='LEGGER XII AKL'!B23 -> Jingga Nur Qalam | C24: ='LEGGER XII AKL'!C23 -> 0067481076 | D24: - | E24: - | F24: - | G24: - | H24: - | I24: - | J24: - | K24: - | L24: - | M24: - | N24: - | O24: -
A25: 10 | B25: ='LEGGER XII AKL'!B24 -> Karina Dwi Sagita | C25: ='LEGGER XII AKL'!C24 -> 0057659388 | D25: - | E25: - | F25: - | G25: - | H25: - | I25: - | J25: - | K25: - | L25: - | M25: - | N25: - | O25: -
A26: 11 | B26: ='LEGGER XII AKL'!B25 -> Larasati | C26: ='LEGGER XII AKL'!C25 -> 3073371186 | D26: - | E26: - | F26: - | G26: - | H26: - | I26: - | J26: - | K26: - | L26: - | M26: - | N26: - | O26: -
A27: 12 | B27: ='LEGGER XII AKL'!B26 -> Lia Apriyani | C27: ='LEGGER XII AKL'!C26 -> 0074403542 | D27: - | E27: - | F27: - | G27: - | H27: - | I27: - | J27: - | K27: - | L27: - | M27: - | N27: - | O27: -
... A55: 40 | B55: ='LEGGER XII AKL'!B54 -> 0 | C55: ='LEGGER XII AKL'!C54 -> 0 | D55: - | E55: - | F55: - | G55: - | H55: - | I55: - | J55: - | K55: - | L55: - | M55: - | N55: - | O55: -
